Workbook

Sheet 1. Caracteristicas de dominio
C3: Entradas | F3: Salidas | I3: Consultas | L3: Archivos Internos | O3: Archivos Externos
C4: ítem | D4: Complejidad | F4: ítem | G4: Complejidad | I4: ítem | J4: Complejidad | L4: ítem | M4: Complejidad | O4: ítem | P4: Complejidad
C5: Inicio de sesión | D5: Bajo | F5: Consolidado de asistencia, incluyendo correciones autorizadas | G5: Medio | I5: Consultar usuarios, estado y roles asignados | J5: Medio | L5: Usuarios | M5: Bajo | O5: No se identifican AE en el alcance actual
C6: Registrar usuario y asignar sus roles de acceso | D6: Medio | F6: Reporte de entregas, devoluciones y reposiciones de EPP por trabajdor y obra | G6: Alto | I6: Consultar roles, permisos y usuarios asociados | J6: Medio | L6: Roles y permisos | M6: Medio
C7: Actualizar datos, estado y rolaes de acceso del usuario | D7: Medio | F7: Acta Semanal de seguimiento con avances, incidencia, participantes, firmas y aprobacion | G7: Alto | I7: Consultar obras, cuadrillas y periodos de asignacion | J7: Bajo | L7: Obras | M7: Bajo
C8: Desactivar usuario, finalizar sus roles activos y registrar la operacion en auditoria | D8: Bajo | I8: Consultar trabajadores, cargos, especialidades, certificaciones y cuadrillas | J8: Bajo | L8: Trabajadores | M8: Bajo
C9: Registrar rol con sus permisos asociados | D9: Medio | I9: Consultar asignaciones de trabajdores y cuadrillas por obra | J9: Medio | L9: Asignaciones trabajador-obra | M9: Bajo
C10: Modificar rol, permisos asociados y asignaciones de roles a usuarios | D10: Medio | I10: Consultar actividades, responsables, trabajadores e incidencias relacionadas | J10: Medio | L10: Asistencias | M10: Bajo
C11: Registrar obra | D11: Bajo | I11: Consultar avances, evidencias y su relacion con actas de seguimiento | J11: Alto | L11: Actividades de obra | M11: Bajo
C12: Actualizar obra / cambiar estado | D12: Bajo | I12: Consultar incidencias y actividades afectadas | J12: Medio | L12: Avances de obra | M12: Medio
C13: Registrar trabajador | D13: Medio | I13: Consultar tipos de EPP, equipos disponibles, condicion y movimientos de inventario | J13: Bajo | L13: Evidencias de avance | M13: Bajo
C14: Actualizar o desactivar trabajador, incluyendo cargo, especialidades y vigencia de certificaciones | D14: Bajo | I14: Consultar entregas, devoluciones, resposiciones e historila de EPP por trabajador y obra | J14: Alto | L14: Actas de seguimiento | M14: Medio
C15: Asignar trabajador a una obra, especialidad y cuadrilla, inidcando periodo, contratacion y responsabilidad | D15: Alto | I15: Consultar herramientas por categoria, tipo, condicion y estado | J15: Bajo | L15: Incidencias de obra | M15: Bajo
C16: Registrar entrada y salida del trabajador y gestionar correciones autorizadas de asistencia con almacenamiento local y sincronización posterior | D16: Alto | I16: Consultar enregas, devolcuiones e incidencias por trabajdor y obra | J16: Alto | L16: Inventario / stock de EPP | M16: Medio
C17: Registrar actividad, responsible y trabajadores asignados | D17: Alto | L17: Movimientos de EPP | M17: Medio
C18: Actualizar actividad, responsible, trabajadores participantes y estado de ejecucion exigiendo una justificación cuando sea marcada como incompleta o retrasada | D18: Alto | L18: Inventario / stock de herramientas | M18: Bajo
C19: Registrar avance físico de una actividad y asociarlo con el periodo de seguimiento correspondiente con almacenamiento local y sincronización posterior | D19: Medio | L19: Movimientos e incidencias de herramientas | M19: Medio
C20: Cargar evidencia del avance con archivo, ubicacion, fecha, usuario y datos de sincronizacion con almacenamiento local y envío posterior. | D20: Alto | L20: Auditoría | M20: Bajo
C21: Elaborar ela cta con avances, incidencias, participantes, firmas y estado de aprobacion | D21: Alto
C22: Registrar incidencia de obra y asociar las actividades afectadas | D22: Alto
C23: Registrar tipo de EPP, equipo individual y movimiento autorizado de entrada al inventario | D23: Medio
C24: Registrar entrega o devolucion de EPP, condicion del equipo, constancia y movimiento de inventario sin conexión y sincronizarlos posteriormente | D24: Alto
C25: Registrar solicitud, aprobacion y ejecucion de resposicion de EPP, actualizando sus movimiento de inventario | D25: Alto
C26: Registrar / actualizar herramienta, categoria, tipo, condicion y estado en inventario sin conexión y sincronizarlos posteriormente | D26: Medio
C27: Asignar herramienta a un trabajador y obra, registrando condicion, responsible y fecha de entrega | D27: Alto
C28: Registrar devolucion, daño, perdida u otra incidencia de herramienta, incluyendo resolucion, costo y estado | D28: Alto
C31: Tabla Resumen
D32: Bajo | E32: Medio | F32: Alto
C33: Entradas | D33: =COUNTIF(D$5:D$28,"Bajo") -> 5 | E33: =COUNTIF(D$5:D$28,"Medio") -> 8 | F33: =COUNTIF(D5:D28,"Alto") -> 11
C34: Salidas | D34: =COUNTIF(G$5:G$6,"Bajo") -> 0 | E34: =COUNTIF(G$5:G$6,"Medio") -> 1 | F34: =COUNTIF(G$5:G$7,"Alto") -> 2
C35: Consultas | D35: =COUNTIF(J$5:J$16,"Bajo") -> 4 | E35: =COUNTIF(J$5:J$16,"Medio") -> 5 | F35: =COUNTIF(J$5:J$16,"Alto") -> 3
C36: Archivos internos | D36: =COUNTIF(M$5:M$20,"Bajo") -> 10 | E36: =COUNTIF(M$5:M$20,"Medio") -> 6 | F36: =COUNTIF(M$5:M$20,"Alto") -> 0
C37: Archivos Externos | D37: =COUNTIF(P$5:P$29,"Bajo") -> 0 | E37: =COUNTIF(P$5:P$29,"Medio") -> 0 | F37: =COUNTIF(P$5:P$29,"Alto") -> 0

Sheet 2. Preguntas
A1: Preguntas | L1: Valor ( 0 - 5)
A2: 1. ¿Requiere el sistema copias de seguridad y de recuperación fiables? | L2: 3
A3: 2. ¿Se requiere comunicaciòn de datos ? | L3: 5
A4: 3. ¿Existen funciones de procesamiento distribuído? | L4: 4
A5: 4. ¿Es crítico el rendimiento? | L5: 5
A6: 5. ¿Se ejecutará el sistema en un entorno operativo existente y fuertemente utilizado? | L6: 3
A7: 6. ¿Requiere le sistema entrada de datos interactiva? | L7: 5
A8: 7. ¿Requiere la entrada de datos interactiva que las transacciones de entrada se lleven a cabo sobre múltiples pantallas u operaciones? | L8: 2
A9: 8. ¿Se actualizan los archivos maestros de forma interactiva? | L9: 4
A10: 9. ¿Son complejas las entradas, las salidas, los archivos o las peticiones? | L10: 4
A11: 10. ¿Es complejo el procesamiento interno? | L11: 4
A12: 11. ¿Se ha diseñado el código para que sea reutilizable? | L12: 2
A13: 12. ¿Están incluidas en el diseño la conversión y la instalación? | L13: 2
... A15: 14. ¿Se ha diseñado la aplicación para facilitar los cambios y para ser fácilmente utilizada por el usuario? | L15: 4
K16: Total | L16: =SUM(L2:L15) -> 47

Sheet 3. Punto de Función
B2: Cuenta Total | I2: Tipo de función | J2: Peso del factor complejidad
C3: Bajo | D3: Promedio | E3: Alto | F3: Total | J3: Bajo | K3: Promedio | L3: Alto
B4: Entradas | C4: ='1. Caracteristicas de dominio'!D33 -> 5 | D4: ='1. Caracteristicas de dominio'!E33 -> 8 | E4: ='1. Caracteristicas de dominio'!F33 -> 11 | F4: =(C4*J4)+(D4*K4)+(E4*L4) -> 113 | I4: Entradas | J4: 3 | K4: 4 | L4: 6
B5: Salidas | C5: ='1. Caracteristicas de dominio'!D34 -> 0 | D5: ='1. Caracteristicas de dominio'!E34 -> 1 | E5: ='1. Caracteristicas de dominio'!F34 -> 2 | F5: =(C5*J5)+(D5*K5)+(E5*L5) -> 19 | I5: Salidas | J5: 4 | K5: 5 | L5: 7
B6: Arch.Internos | C6: ='1. Caracteristicas de dominio'!D36 -> 10 | D6: ='1. Caracteristicas de dominio'!E36 -> 6 | E6: ='1. Caracteristicas de dominio'!F36 -> 0 | F6: =(C6*J6)+(D6*K6)+(E6*L6) -> 130 | I6: Arch.Internos | J6: 7 | K6: 10 | L6: 15
B7: Arch.Externos | C7: ='1. Caracteristicas de dominio'!D37 -> 0 | D7: ='1. Caracteristicas de dominio'!E37 -> 0 | E7: ='1. Caracteristicas de dominio'!F37 -> 0 | F7: =(C7*J7)+(D7*K7)+(E7*L7) -> 0 | I7: Arch.Externos | J7: 5 | K7: 7 | L7: 10
B8: Consultas | C8: ='1. Caracteristicas de dominio'!D35 -> 4 | D8: ='1. Caracteristicas de dominio'!E35 -> 5 | E8: ='1. Caracteristicas de dominio'!F35 -> 3 | F8: =(C8*J8)+(D8*K8)+(E8*L8) -> 50 | I8: Consultas | J8: 3 | K8: 4 | L8: 6
F9: =SUM(F4:F8) -> 312
J10: Lenguajes | K10: LDC
B11: PF | C11: =F9 -> 312 | J11: C# | K11: 54
B12: PFA | C12: =C11*(0.65+0.01*E14) -> 349.44 | J12: JavaScript | K12: 47
B13: Prom. LC | C13: =K13 -> 50.5 | E13: Preguntas | J13: Promedio | K13: =AVERAGE(K11:K12) -> 50.5
B14: TLDC | C14: =C12*C13 -> 17646.72 | E14: ='2. Preguntas'!L16 -> 47
B15: MF | C15: =C14/1000 -> 17.64672

Sheet 4. Base de Datos
C1: Kb
B2: Base de Datos SQL Vacía | C2: 8192
B6: cargos | C6: cargo | D6: cargo | F6: especialidades | G6: especialidad | H6: especialidad | J6: roles | K6: rol | L6: rol
B7: Nombre del Campo | C7: Tipo de dato | D7: Tamaño de bytes | F7: Nombre del Campo | G7: Tipo de dato | H7: Tamaño de bytes | J7: Nombre del Campo | K7: Tipo de dato | L7: Tamaño de bytes
B8: id_cargo | C8: INTEGER | D8: 4 | F8: id_especialidad | G8: INTEGER | H8: 4 | J8: id_rol | K8: INTEGER | L8: 4
B9: nombre | C9: VARCHAR(60) | D9: 60 | F9: nombre | G9: VARCHAR(60) | H9: 60 | J9: nombre | K9: VARCHAR(50) | L9: 50
B10: descripcion | C10: VARCHAR(200) | D10: 200 | F10: descripcion | G10: VARCHAR(200) | H10: 200 | J10: descripcion | K10: VARCHAR(200) | L10: 200
B11: activo | C11: BOOLEAN | D11: 1 | F11: activo | G11: BOOLEAN | H11: 1 | J11: activo | K11: BOOLEAN | L11: 1
C12: Total | D12: =SUM(D8:D11) -> 265 | G12: Total | H12: =SUM(H8:H11) -> 265 | K12: Total | L12: =SUM(L8:L11) -> 255
B14: permisos | C14: permiso | D14: permiso | F14: trabajadores | G14: trabajador | H14: trabajador | J14: usuarios | K14: usuario | L14: usuario
B15: Nombre del Campo | C15: Tipo de dato | D15: Tamaño de bytes | F15: Nombre del Campo | G15: Tipo de dato | H15: Tamaño de bytes | J15: Nombre del Campo | K15: Tipo de dato | L15: Tamaño de bytes
B16: id_permiso | C16: INTEGER | D16: 4 | F16: id_trabajador | G16: INTEGER | H16: 4 | J16: id_usuario | K16: INTEGER | L16: 4
B17: codigo | C17: VARCHAR(60) | D17: 60 | F17: id_cargo | G17: INT | H17: 4 | J17: id_trabajador | K17: INT | L17: 4
B18: nombre | C18: VARCHAR(80) | D18: 80 | F18: cedula | G18: VARCHAR(20) | H18: 20 | J18: nombre_usuario | K18: VARCHAR(60) | L18: 60
B19: descripcion | C19: VARCHAR(200) | D19: 200 | F19: primer_nombre | G19: VARCHAR(50) | H19: 50 | J19: password_hash | K19: VARCHAR(255) | L19: 255
B20: activo | C20: BOOLEAN | D20: 1 | F20: segundo_nombre | G20: VARCHAR(50) | H20: 50 | J20: estado | K20: VARCHAR(15) | L20: 15
C21: Total | D21: =SUM(D16:D20) -> 345 | F21: primer_apellido | G21: VARCHAR(50) | H21: 50 | J21: creado_en | K21: TIMESTAMPTZ(0) | L21: 8
F22: segundo_apellido | G22: VARCHAR(50) | H22: 50 | J22: ultimo_acceso | K22: TIMESTAMPTZ(0) | L22: 8
F23: telefono | G23: VARCHAR(20) | H23: 20 | K23: Total | L23: =SUM(L16:L22) -> 354
F24: correo | G24: VARCHAR(100) | H24: 100
F25: direccion | G25: VARCHAR(200) | H25: 200
F26: fecha_ingreso | G26: DATE | H26: 4
F27: estado | G27: VARCHAR(15) | H27: 15
G28: Total | H28: =SUM(H16:H27) -> 567
B30: usuarios_rol | C30: usuario_rol | D30: usuario_rol | F30: roles_permiso | G30: rol_permiso | H30: rol_permiso | J30: auditorias | K30: auditoria | L30: auditoria
B31: Nombre del Campo | C31: Tipo de dato | D31: Tamaño de bytes | F31: Nombre del Campo | G31: Tipo de dato | H31: Tamaño de bytes | J31: Nombre del Campo | K31: Tipo de dato | L31: Tamaño de bytes
B32: id_usuario_rol | C32: INTEGER | D32: 4 | F32: id_rol | G32: INT | H32: 4 | J32: id_auditoria | K32: BIGINT | L32: 8
B33: id_usuario | C33: INT | D33: 4 | F33: id_permiso | G33: INT | H33: 4 | J33: id_usuario | K33: INT | L33: 4
B34: id_rol | C34: INT | D34: 4 | G34: Total | H34: =SUM(H32:H33) -> 8 | J34: entidad | K34: VARCHAR(60) | L34: 60
B35: fecha_inicio | C35: DATE | D35: 4 | J35: id_registro | K35: VARCHAR(50) | L35: 50
B36: fecha_fin | C36: DATE | D36: 4 | J36: accion | K36: VARCHAR(20) | L36: 20
C37: Total | D37: =SUM(D32:D36) -> 20 | J37: campo | K37: VARCHAR(60) | L37: 60
J38: valor_anterior | K38: VARCHAR(1000) | L38: 1000
J39: valor_nuevo | K39: VARCHAR(1000) | L39: 1000
J40: fecha_hora | K40: TIMESTAMPTZ(0) | L40: 8
J41: ip_origen | K41: INET | L41: 19
J42: uuid_operacion | K42: UUID | L42: 16
K43: Total | L43: =SUM(L32:L42) -> 2245
B45: obras | C45: obra | D45: obra | F45: cuadrillas | G45: cuadrilla | H45: cuadrilla | J45: trabajadores_especialidad | K45: trabajador_especialidad | L45: trabajador_especialidad
B46: Nombre del Campo | C46: Tipo de dato | D46: Tamaño de bytes | F46: Nombre del Campo | G46: Tipo de dato | H46: Tamaño de bytes | J46: Nombre del Campo | K46: Tipo de dato | L46: Tamaño de bytes
...

Sheet 5. Estimación del esfuerzo
D6: A | E6: 2.94
H8: Factor de los indicadores de escala | M8: Factores de escala
I9: V.Cualitativo | J9: V.Cuantitativo | M9: Fact. de escala | N9: Muy bajo | O9: Bajo | P9: Nominal | Q9: Alto | R9: Muy Alto | S9: Ext. Alto
B10: MF | C10: ='3. Punto de Función'!C15 -> 17.64672 | H10: PREC | I10: Nominal | J10: =IF(EXACT(I10,$N$9),N10,IF(EXACT(I10,$O$9),O10,IF(EXACT(I10,$P$9),P10,IF(EXACT(I10,$Q$9),Q10,IF(EXACT(I10,$R$9),R10,0))))) -> 3.72 | M10: PREC | N10: 6.2 | O10: 4.96 | P10: 3.72 | Q10: 2.48 | R10: 1.24 | S10: 0
B11: B | C11: =1.01+(0.01*J15) -> 1.1997 | H11: FLEX | I11: =P9 -> Nominal | J11: =IF(EXACT(I11,$N$9),N11,IF(EXACT(I11,$O$9),O11,IF(EXACT(I11,$P$9),P11,IF(EXACT(I11,$Q$9),Q11,IF(EXACT(I11,$R$9),R11,0))))) -> 3.04 | M11: FLEX | N11: 5.07 | O11: 4.05 | P11: 3.04 | Q11: 2.03 | R11: 1.01 | S11: 0
B12: Esfuerzo | C12: =$E$6*(C10^C11)*J39 -> 92.038626 | D12: Hombres / Mes | H12: RESL | I12: Nominal | J12: =IF(EXACT(I12,$N$9),N12,IF(EXACT(I12,$O$9),O12,IF(EXACT(I12,$P$9),P12,IF(EXACT(I12,$Q$9),Q12,IF(EXACT(I12,$R$9),R12,0))))) -> 4.24 | M12: RESL | N12: 7.07 | O12: 5.65 | P12: 4.24 | Q12: 2.83 | R12: 1.41 | S12: 0
A13: Esfuerzo Redondeado | C13: =ROUNDUP($E$6*(C10^C11)*J39,0) -> 93 | D13: Hombres / Mes | H13: TEAM | I13: Nominal | J13: =IF(EXACT(I13,$N$9),N13,IF(EXACT(I13,$O$9),O13,IF(EXACT(I13,$P$9),P13,IF(EXACT(I13,$Q$9),Q13,IF(EXACT(I13,$R$9),R13,0))))) -> 3.29 | M13: TEAM | N13: 5.48 | O13: 4.38 | P13: 3.29 | Q13: 2.19 | R13: 1.1 | S13: 0
H14: PMAT | I14: Nominal | J14: =IF(EXACT(I14,$N$9),N14,IF(EXACT(I14,$O$9),O14,IF(EXACT(I14,$P$9),P14,IF(EXACT(I14,$Q$9),Q14,IF(EXACT(I14,$R$9),R14,0))))) -> 4.68 | M14: PMAT | N14: 7.8 | O14: 6.24 | P14: 4.68 | Q14: 3.12 | R14: 1.56 | S14: 0
I15: Total | J15: =SUM(J10:J14) -> 18.97 | P15: =SUM(P10:P14) -> 18.97
B18: Exponente del esfuerzo | E18: =0.28+(0.002*J15) -> 0.31794
B19: Tdes | C19: =2.4*(C12^E18) -> 10.107317 | D19: Meses
A20: Tdes Redondeado | C20: =ROUNDUP(2.4*(C12^E18),0) -> 11 | D20: Meses | H20: Factor de Esfuerzo Compuesto | M20: Factor esfuerzo compuesto
I21: V.Cualitativo | J21: V.Cuantitativo | M21: Indice | N21: Muy bajo | O21: Bajo | P21: Nominal | Q21: Alto | R21: Muy Alto | S21: Ext. Alto
G22: Producto | H22: RELY | I22: =P21 -> Nominal | J22: =IF(EXACT(I22,$N$21),N22,IF(EXACT(I22,$O$21),O22,IF(EXACT(I22,$P$21),P22,IF(EXACT(I22,$Q$21),Q22,IF(EXACT(I22,$R$21),R22,S22))))) -> 1 | M22: RELY | N22: 0.75 | O22: 0.88 | P22: 1 | Q22: 1.15 | R22: 1.39
H23: DATA | I23: Nominal | J23: =IF(EXACT(I23,$N$21),N23,IF(EXACT(I23,$O$21),O23,IF(EXACT(I23,$P$21),P23,IF(EXACT(I23,$Q$21),Q23,IF(EXACT(I23,$R$21),R23,S23))))) -> 1 | M23: DATA | O23: 0.93 | P23: 1 | Q23: 1.09 | R23: 1.19
H24: CPLX | I24: =P21 -> Nominal | J24: =IF(EXACT(I24,$N$21),N24,IF(EXACT(I24,$O$21),O24,IF(EXACT(I24,$P$21),P24,IF(EXACT(I24,$Q$21),Q24,IF(EXACT(I24,$R$21),R24,S24))))) -> 1 | M24: CPLX | N24: 0.75 | O24: 0.88 | P24: 1 | Q24: 1.15 | R24: 1.3 | S24: 1.66
B25: Personal Requerido | H25: RUSE | I25: =P21 -> Nominal | J25: =IF(EXACT(I25,$N$21),N25,IF(EXACT(I25,$O$21),O25,IF(EXACT(I25,$P$21),P25,IF(EXACT(I25,$Q$21),Q25,IF(EXACT(I25,$R$21),R25,S25))))) -> 1 | M25: RUSE | O25: 0.91 | P25: 1 | Q25: 1.14 | R25: 1.29 | S25: 1.49
B26: CH | C26: =C12/C19 -> 9.1061379 | D26: Hombres | H26: DOCU | I26: =P21 -> Nominal | J26: =IF(EXACT(I26,$N$21),N26,IF(EXACT(I26,$O$21),O26,IF(EXACT(I26,$P$21),P26,IF(EXACT(I26,$Q$21),Q26,IF(EXACT(I26,$R$21),R26,S26))))) -> 1 | M26: DOCU | N26: 0.89 | O26: 0.95 | P26: 1 | Q26: 1.06 | R26: 1.13
A27: CH Redondeado | C27: =ROUNDUP(C12/C19,0) -> 10 | D27: Hombres | G27: Plataforma | H27: TIME | I27: =P21 -> Nominal | J27: =IF(EXACT(I27,$N$21),N27,IF(EXACT(I27,$O$21),O27,IF(EXACT(I27,$P$21),P27,IF(EXACT(I27,$Q$21),Q27,IF(EXACT(I27,$R$21),R27,S27))))) -> 1 | M27: TIME | P27: 1 | Q27: 1.11 | R27: 1.31 | S27: 1.67
H28: STOR | I28: =P21 -> Nominal | J28: =IF(EXACT(I28,$N$21),N28,IF(EXACT(I28,$O$21),O28,IF(EXACT(I28,$P$21),P28,IF(EXACT(I28,$Q$21),Q28,IF(EXACT(I28,$R$21),R28,S28))))) -> 1 | M28: STOR | P28: 1 | Q28: 1.06 | R28: 1.21 | S28: 1.57
H29: PVOL | I29: Nominal | J29: =IF(EXACT(I29,$N$21),N29,IF(EXACT(I29,$O$21),O29,IF(EXACT(I29,$P$21),P29,IF(EXACT(I29,$Q$21),Q29,IF(EXACT(I29,$R$21),R29,S29))))) -> 1 | M29: PVOL | O29: 0.87 | P29: 1 | Q29: 1.15 | R29: 1.3
G30: Personal | H30: ACAP | I30: Nominal | J30: =IF(EXACT(I30,$N$21),N30,IF(EXACT(I30,$O$21),O30,IF(EXACT(I30,$P$21),P30,IF(EXACT(I30,$Q$21),Q30,IF(EXACT(I30,$R$21),R30,S30))))) -> 1 | M30: ACAP | N30: 1.5 | O30: 1.22 | P30: 1 | Q30: 0.83 | R30: 0.67
H31: PCAP | I31: Nominal | J31: =IF(EXACT(I31,$N$21),N31,IF(EXACT(I31,$O$21),O31,IF(EXACT(I31,$P$21),P31,IF(EXACT(I31,$Q$21),Q31,IF(EXACT(I31,$R$21),R31,S31))))) -> 1 | M31: PCAP | N31: 1.37 | O31: 1.16 | P31: 1 | Q31: 0.87 | R31: 0.74
H32: PCON | I32: Nominal | J32: =IF(EXACT(I32,$N$21),N32,IF(EXACT(I32,$O$21),O32,IF(EXACT(I32,$P$21),P32,IF(EXACT(I32,$Q$21),Q32,IF(EXACT(I32,$R$21),R32,S32))))) -> 1 | M32: PCON | N32: 1.24 | O32: 1.1 | P32: 1 | Q32: 0.92 | R32: 0.84
H33: AEXP | I33: Nominal | J33: =IF(EXACT(I33,$N$21),N33,IF(EXACT(I33,$O$21),O33,IF(EXACT(I33,$P$21),P33,IF(EXACT(I33,$Q$21),Q33,IF(EXACT(I33,$R$21),R33,S33))))) -> 1 | M33: AEXP | N33: 1.22 | O33: 1.1 | P33: 1 | Q33: 0.89 | R33: 0.81
H34: PEXP | I34: Nominal | J34: =IF(EXACT(I34,$N$21),N34,IF(EXACT(I34,$O$21),O34,IF(EXACT(I34,$P$21),P34,IF(EXACT(I34,$Q$21),Q34,IF(EXACT(I34,$R$21),R34,S34))))) -> 1 | M34: PEXP | N34: 1.25 | O34: 1.12 | P34: 1 | Q34: 0.88 | R34: 0.81
H35: LTEX | I35: Nominal | J35: =IF(EXACT(I35,$N$21),N35,IF(EXACT(I35,$O$21),O35,IF(EXACT(I35,$P$21),P35,IF(EXACT(I35,$Q$21),Q35,IF(EXACT(I35,$R$21),R35,S35))))) -> 1 | M35: LTEX | N35: 1.22 | O35: 1.1 | P35: 1 | Q35: 0.91 | R35: 0.84
G36: Proyecto | H36: TOOL | I36: Nominal | J36: =IF(EXACT(I36,$N$21),N36,IF(EXACT(I36,$O$21),O36,IF(EXACT(I36,$P$21),P36,IF(EXACT(I36,$Q$21),Q36,IF(EXACT(I36,$R$21),R36,S36))))) -> 1 | M36: TOOL | N36: 1.24 | O36: 1.12 | P36: 1 | Q36: 0.86 | R36: 0.72
H37: SITE | I37: Nominal | J37: =IF(EXACT(I37,$N$21),N37,IF(EXACT(I37,$O$21),O37,IF(EXACT(I37,$P$21),P37,IF(EXACT(I37,$Q$21),Q37,IF(EXACT(I37,$R$21),R37,S37))))) -> 1 | M37: SITE | N37: 1.25 | O37: 1.1 | P37: 1 | Q37: 0.92 | R37: 0.84 | S37: 0.78
H38: SCED | I38: Nominal | J38: =IF(EXACT(I38,$N$21),N38,IF(EXACT(I38,$O$21),O38,IF(EXACT(I38,$P$21),P38,IF(EXACT(I38,$Q$21),Q38,IF(EXACT(I38,$R$21),R38,S38))))) -> 1 | M38: SCED | N38: 1.29 | O38: 1.1 | P38: 1 | Q38: 1 | R38: 1
I39: Total | J39: =PRODUCT(J22:J26,J27:J29,J30:J35,J36:J38) -> 1

Sheet 6. Distribución
C2: MF | D2: ='3. Punto de Función'!C15 -> 17.64672
C3: Esfuerzo | D3: ='5. Estimación del esfuerzo'!C12 -> 92.038626
C4: Tdes | D4: ='5. Estimación del esfuerzo'!C20 -> 11
C5: CH | D5: ='5. Estimación del esfuerzo'!C27 -> 10 | L5: INDICADOR/MODO | M5: FASES | N5: PEQUEÑO 2 mf | O5: INTERMEDIO8 mf | P5: MEDIO 32 mf | Q5: GRANDE 128 mf | R5: MUY GRANDE 512 mf
L6: ESFUERZO | N6: 2 | O6: 8 | P6: 32 | Q6: 128 | R6: 512
L7: porcentajes | M7: Estudio Preliminar | N7: 0.07 | O7: 0.07 | P7: 0.07 | Q7: 0.07 | R7: 0.07
M8: Análisis | N8: 0.17 | O8: 0.17 | P8: 0.17 | Q8: 0.17 | R8: 0.17
M9: Diseño y desarrollo | N9: 0.64 | O9: 0.61 | P9: 0.58 | Q9: 0.55 | R9: 0.52
C10: =(D2-O6)/(P6-O6) -> 0.40194667 | M10: Diseño | N10: 0.27 | O10: 0.26 | P10: 0.25 | Q10: 0.24 | R10: 0.23
M11: Desarrollo | N11: 0.37 | O11: 0.35 | P11: 0.33 | Q11: 0.31 | R11: 0.29
M12: Prueba e implantación | N12: 0.19 | O12: 0.22 | P12: 0.25 | Q12: 0.28 | R12: 0.31
L13: TIEMPO DE DESARROLLO
L14: porcentajes | M14: Estudio Preliminar | N14: 0.16 | O14: 0.18 | P14: 0.2 | Q14: 0.22 | R14: 0.24
M15: Análisis | N15: 0.24 | O15: 0.25 | P15: 0.26 | Q15: 0.27 | R15: 0.28
M16: Diseño y desarrollo | N16: 0.56 | O16: 0.52 | P16: 0.48 | Q16: 0.44 | R16: 0.4
M17: Prueba e implant | N17: 0.2 | O17: 0.23 | P17: 0.26 | Q17: 0.29 | R17: 0.32
I19: Distribución | M19: Salarios ($)
B20: Etapas | C20: %Esf | D20: Esf | E20: %Tdes | F20: Tdes | G20: CH | H20: CH real | I20: Jefe de Proyecto | J20: Analista Programador | K20: Programador | M20: =I20 -> Jefe de Proyecto | N20: 700
B21: Est. Preliminar | C21: =O7+$C$10*(P7-O7) -> 0.07 | D21: =$D$3*C21 -> 6.4427038 | E21: =O14+$C$10*(P14-O14) -> 0.18803893 | F21: =$D$4*E21 -> 2.0684283 | G21: =D21/F21 -> 3.1147823 | H21: =ROUND(G21,0) -> 3 | I21: 1 | J21: 0 | K21: 0 | M21: =J20 -> Analista Programador | N21: 540
B22: Análisis | C22: =O8 +$C$10*(P8-O8) -> 0.17 | D22: =$D$3*C22 -> 15.646566 | E22: =O15+$C$10*(P15-O15) -> 0.25401947 | F22: =$D$4*E22 -> 2.7942141 | G22: =D22/F22 -> 5.5996304 | H22: =ROUND(G22,0) -> 6 | I22: 1 | J22: 0 | K22: 0 | M22: =K20 -> Programador | N22: 250
B23: Diseño y Desarrollo | C23: =O9+$C$10*(P9-O9) -> 0.5979416 | D23: =$D$3*C23 -> 55.033723 | E23: =O16+$C$10*(P16-O16) -> 0.50392213 | F23: =$D$4*E23 -> 5.5431435 | G23: =D23/F23 -> 9.9282516 | H23: =ROUND(G23,0) -> 10 | I23: 1 | J23: 0 | K23: 1
B24: Prueba e Implant | C24: =O12+$C$10*(P12-O12) -> 0.2320584 | D24: =$D$3*C24 -> 21.358336 | E24: =O17+$C$10*(P17-O17) -> 0.2420584 | F24: =$D$4*E24 -> 2.6626424 | G24: =D24/F24 -> 8.0214813 | H24: =ROUND(G24,0) -> 8 | I24: 1 | J24: 0 | K24: 1
C25: =SUM(C22:C24) -> 1 | D25: =SUM(D22:D24) -> 92.038626 | E25: =SUM(E22:E24) -> 1 | F25: =SUM(F22:F24) -> 11
B27: Costo Total del Proyecto = CD + CI
B28: CD = Costos de fuerza de trabajo + costo de uso de medios tecnico + costo de materiales + otros gastos
B29: CFT = Sumatoria de los costos en las etapas
B31: Fuerza de Trabajo | E31: Costo de uso de medios tecnicos | J31: Consumo de Computadora
B32: CFT1 | C32: =(F21*I21*$N$20)+(F21*J21*$N$21)+(F21*K21*$N$22) -> 1447.8998 | E32: CUMT1 | F32: =F21*H21*$K$40 -> 74.162461 | J32: h | K32: KW
B33: CFT2 | C33: =(F22*I22*$N$20)+(F22*J22*$N$21)+(F22*K22*$N$22) -> 1955.9499 | E33: CUMT2 | F33: =F22*H22*$K$40 -> 200.3703 | J33: 8 | K33: 2.2
B34: CFT3 | C34: =(F23*I23*$N$20)+(F23*J23*$N$21)+(F23*K23*$N$22) -> 5265.9863 | E34: CUMT3 | F34: =F23*H23*$K$40 -> 662.48879 | J34: 205 | K34: =(J34*K33)/J33 -> 56.375
B35: CFT4 | C35: =(F24*I24*$N$20)+(F24*J24*$N$21)+(F24*K24*$N$22) -> 2529.5103 | E35: CUMT4 | F35: =F24*H24*$K$40 -> 254.58057
B36: Total | C36: =SUM(C32:C35) -> 11199.346 | E36: Total | F36: =SUM(F32:F35) -> 1191.6021 | J36: Cobro de UNIOFENOSA
J37: h | K37: kw
B38: Costo de Materiales | E38: Otros Gatos | J38: 1 | K38: 0.212
B39: CM1 | C39: =F21*'Lista de Materiales'!$I$15 -> 3.4560449 | E39: Total | F39: =SUM(N20:N22) -> 1490
B40: CM2 | C40: =F22*'Lista de Materiales'!$I$15 -> 4.6687283 | J40: Total KW | K40: =K38*K34 -> 11.9515
B41: CM3 | C41: =F23*'Lista de Materiales'!$I$15 -> 9.2617922
B42: CM4 | C42: =F24*'Lista de Materiales'!$I$15 -> 4.4488909
B43: Total | C43: =SUM(C39:C42) -> 21.835456 | F43: TIPO DE CAMBIO
F44: 36.6243
...

Sheet Lista de Materiales
D3: Material | E3: Proyección Mensual | F3: Gomper | G3: Jardin | H3: Hispamer | I3: Precio Favorable
D4: Hojas Blancas | E4: 10 | F4: =2*E4 -> 20 | G4: =1*E4 -> 10 | H4: =1.5*E4 -> 15 | I4: =SMALL(F4:H4,1) -> 10
D5: Lápiz Grafito | E5: 0 | F5: =6.52*E5 -> 0 | G5: =7.71*E5 -> 0 | I5: =SMALL(F5:H5,1) -> 0
D6: Lapicero | E6: 3 | F6: =(53.17/12)*E6 -> 13.2925 | G6: =5.49*E6 -> 16.47 | H6: =(0.4*M7)*E6 -> 44.04 | I6: =SMALL(F6:H6,1) -> 13.2925 | M6: Cambio a Dolar
D7: Folder | E7: 1 | F7: =281.29/100 -> 2.8129 | G7: =48.09/10 -> 4.809 | H7: =319.98/12 -> 26.665 | I7: =SMALL(F7:H7,1) -> 2.8129 | M7: 36.7
D8: Engrapadora | E8: =1/6 -> 0.16666667 | F8: =49.04*E8 -> 8.1733333 | G8: =59.51*E8 -> 9.9183333 | H8: =(4.13*M7)*E8 -> 25.261833 | I8: =SMALL(F8:H8,1) -> 8.1733333
D9: Grapas | E9: =1/6 -> 0.16666667 | F9: =30.13*E9 -> 5.0216667 | G9: =37.03*E9 -> 6.1716667 | I9: =SMALL(F9:H9,1) -> 5.0216667
D10: Resaltador | E10: 2 | F10: =23.16*E10 -> 46.32 | G10: =12.28*E10 -> 24.56 | H10: =(0.3*M7)*E10 -> 22.02 | I10: =SMALL(F10:H10,1) -> 22.02
D11: Saca Puntas | E11: 0 | F11: =8.86*E11 -> 0 | G11: =10.48*E11 -> 0 | H11: =0.24*M7*E11 -> 0 | I11: =SMALL(F11:H11,1) -> 0
D12: Borradores | E12: 0 | F12: =5.97*E12 -> 0 | G12: =7.87*E12 -> 0 | H12: =0.12*M7*E12 -> 0 | I12: =SMALL(F12:H12,1) -> 0
D13: TOTAL | F13: =SUM(F4:F12) -> 95.6204 | G13: =SUM(G4:G12) -> 71.929 | H13: =SUM(H4:H12) -> 132.98683 | I13: =SUM(I4:I12) -> 61.3204
G15: Total en Dolares | I15: =I13/M7 -> 1.6708556
